Workbook

Sheet Focused GAs -MOPNG DATA
A1: Natio+A1:Q11nal PNG Drive 2.0 Targets - Focus GAs (110) | H1: Cummulative | L1: PNG Drive before 16th March | P1: 16th March 2026 | T1: 17th March 2026 | X1: 18th March 2026 | AB1: 19th March 2026 | AF1: 20th March 2026 | AJ1: 21st March 2026 | AN1: 22nd March 2026 | AR1: 23rd March 2026 | AV1: 24th March 2026 | AZ1: 25th March 2026 | BD1: 26th March 2026 | BH1: 27th March 2026 | BL1: 28th March 2026 | BP1: 30th March 2026 | BT1: 31st March 2026 | BX1: 1st April 2026 | CB1: 2nd April 2026 | CF1: 3rd April 2026 | CJ1: Total 16th Mar-Till Date
A2: S No | B2: GA ID | C2: GA Name | D2: DPNG Target (Drive) | G2: Commercial Connections | H2: Cumm. DPNG | K2: Commercial Connections Completed (Gas-in) | L2: DPNG Progress | O2: Commercial Connections Completed (Gas-in) | P2: DPNG Progress | S2: Commercial Connections Completed (Gas-in) | T2: DPNG Progress | W2: Commercial Connections Completed (Gas-in) | X2: DPNG Progress | AA2: Commercial Connections Completed (Gas-in) | AB2: DPNG Progress | AE2: Commercial Connections Completed (Gas-in) | AF2: DPNG Progress | AI2: Commercial Connections Completed (Gas-in) | AJ2: DPNG Progress | AM2: Commercial Connections Completed (Gas-in) | AN2: DPNG Progress | AQ2: Commercial Connections Completed (Gas-in) | AR2: DPNG Progress | AU2: Commercial Connections Completed (Gas-in) | AV2: DPNG Progress | AY2: Commercial Connections Completed (Gas-in) | AZ2: DPNG Progress | BC2: Commercial Connections Completed (Gas-in) | BD2: DPNG Progress | BG2: Commercial Connections Completed (Gas-in) | BH2: DPNG Progress | BK2: Commercial Connections Completed (Gas-in) | BL2: DPNG Progress | BO2: Commercial Connections Completed (Gas-in) | BP2: DPNG Progress | BS2: Commercial Connections Completed (Gas-in) | BT2: DPNG Progress | BW2: Commercial Connections Completed (Gas-in) | BX2: DPNG Progress | CA2: Commercial Connections Completed (Gas-in) | CB2: DPNG Progress | CE2: Commercial Connections Completed (Gas-in) | CF2: DPNG Progress | CI2: Commercial Connections Completed (Gas-in) | CJ2: DPNG Progress | CM2: Commercial Connections Completed (Gas-in)
D3: Connections | E3: Connected to Billed | F3: Registrations | H3: LMC | I3: NGC | J3: Registrations | L3: LMC | M3: NGC | N3: Registrations | P3: New Connections | Q3: Connected to Billed | R3: Registrations | T3: New Connections | U3: Connected to Billed | V3: Registrations | X3: New Connections | Y3: Connected to Billed | Z3: Registrations | AB3: New Connections | AC3: Connected to Billed | AD3: Registrations | AF3: New Connections | AG3: Connected to Billed | AH3: Registrations | AJ3: New Connections | AK3: Connected (Old RFC) to Billed | AL3: Registrations | AN3: New Connections | AO3: Connected (Old RFC) to Billed | AP3: Registrations | AR3: New Connections | AS3: Connected (Old RFC) to Billed | AT3: Registrations | AV3: New Connections | AW3: Connected (Old RFC) to Billed | AX3: Registrations | AZ3: New Connections | BA3: Connected (Old RFC) to Billed | BB3: Registrations | BD3: New Connections | BE3: Connected (Old RFC) to Billed | BF3: Registrations | BH3: New Connections | BI3: Connected (Old RFC) to Billed | BJ3: Registrations | BL3: New Connections | BM3: Connected (Old RFC) to Billed | BN3: Registrations | BP3: New Connections | BQ3: Connected (Old RFC) to Billed | BR3: Registrations | BT3: New Connections | BU3: Connected (Old RFC) to Billed | BV3: Registrations | BX3: New Connections | BY3: Connected (Old RFC) to Billed | BZ3: Registrations | CB3: New Connections | CC3: Connected (Old RFC) to Billed | CD3: Registrations | CF3: New Connections | CG3: Connected (Old RFC) to Billed | CH3: Registrations | CJ3: New Connections | CK3: Connected (Old RFC) to Billed | CL3: Registrations
A4: 1 | B4: 10.37 | C4: Bareilly (EAAA) District, Pilibhit and Rampur Districts | D4: 15000 | E4: 20000 | F4: 30000 | G4: 5 | H4: 1068 | I4: 1068 | J4: 28185 | K4: 0 | L4: 1331 | M4: 1133 | N4: 626 | P4: 9 | Q4: 13 | R4: 0 | S4: 0 | T4: 3 | U4: 6 | V4: 3 | W4: 0 | X4: 4 | Y4: 14 | Z4: 9 | AA4: 0 | AB4: 4 | AC4: 17 | AD4: 13 | AE4: 0 | AF4: 4 | AG4: 17 | AH4: 13 | AI4: 0 | AJ4: 0 | AK4: 10 | AL4: 13 | AM4: 0 | AN4: 0 | AO4: 5 | AP4: 0 | AQ4: 0 | AR4: 4 | AS4: 8 | AT4: 5 | AU4: 0 | AV4: 0 | AW4: 9 | AX4: 3 | AY4: 0 | AZ4: 0 | BA4: 15 | BB4: 3 | BC4: 0 | BD4: 0 | BE4: 15 | BF4: 3 | BG4: 0 | BH4: 20 | BI4: 14 | BJ4: 5 | BK4: 0 | BL4: 7 | BM4: 14 | BN4: 3 | BO4: 0 | BP4: 12 | BQ4: 18 | BR4: 3 | BS4: 0 | BT4: ='All GAs'!AR4 -> 10 | BU4: ='All GAs'!AS4 -> 16 | BV4: ='All GAs'!AT4 -> 10 | BW4: ='All GAs'!AU4 -> 0 | BX4: ='All GAs'!AV4 -> 7 | BY4: ='All GAs'!AW4 -> 17 | BZ4: ='All GAs'!AX4 -> 10 | CA4: ='All GAs'!AY4 -> 0 | ... CI4: ='All GAs'!BG4 -> 0 | CJ4: =AV4+AR4+AN4+AJ4+AF4+AB4+X4+T4+P4+AZ4+BD4+BH4+BL4+BP4+BT4+BX4 -> 84 | CK4: =AW4+AS4+AO4+AK4+AG4+AC4+Y4+U4+Q4+BA4+BE4+BI4+BM4+BQ4+BU4+BY4 -> 208 | CL4: =AX4+AT4+AP4+AL4+AH4+AD4+Z4+V4+R4+BB4+BF4+BJ4+BN4+BR4+BV4+BZ4 -> 96 | CM4: =AY4+AU4+AQ4+AM4+AI4+AE4+AA4+W4+S4+BC4+BG4+BK4+BO4+BS4+BW4+CA4 -> 0
A5: 2 | B5: 10.47 | C5: Darjeeling, Jalpaiguri and Uttar Dinajpur Districts | D5: 15000 | E5: 20000 | F5: 30000 | G5: 20 | H5: 12248 | I5: 501 | J5: 17611 | K5: 1 | L5: 5068 | M5: 531 | N5: 2514 | P5: 0 | Q5: 223 | R5: 35 | S5: 0 | T5: 76 | U5: 40 | V5: 123 | W5: 0 | X5: 50 | Y5: 20 | Z5: 38 | AA5: 0 | AB5: 94 | AC5: 10 | AD5: 98 | AE5: 0 | AF5: 94 | AG5: 10 | AH5: 98 | AI5: 0 | AJ5: 71 | AK5: 0 | AL5: 3 | AM5: 1 | AN5: 62 | AO5: 5 | AP5: 2 | AQ5: 0 | AR5: 4 | AS5: 5 | AT5: 5 | AU5: 1 | AV5: 115 | AW5: 7 | AX5: 5 | AY5: 0 | AZ5: 3 | BA5: 8 | BB5: 4 | BC5: 0 | BD5: 68 | BE5: 15 | BF5: 17 | BG5: 0 | BH5: 61 | BI5: 18 | BJ5: 9 | BK5: 0 | BL5: 35 | BM5: 20 | BN5: 25 | BO5: 0 | BP5: 33 | BQ5: 23 | BR5: 37 | BS5: 0 | BT5: ='All GAs'!AR5 -> 71 | BU5: ='All GAs'!AS5 -> 30 | BV5: ='All GAs'!AT5 -> 35 | BW5: ='All GAs'!AU5 -> 0 | BX5: ='All GAs'!AV5 -> 21 | BY5: ='All GAs'!AW5 -> 30 | BZ5: ='All GAs'!AX5 -> 34 | CA5: ='All GAs'!AY5 -> 1 | ... CI5: ='All GAs'!BG5 -> 0 | CJ5: =AV5+AR5+AN5+AJ5+AF5+AB5+X5+T5+P5+AZ5+BD5+BH5+BL5+BP5+BT5+BX5 -> 858 | CK5: =AW5+AS5+AO5+AK5+AG5+AC5+Y5+U5+Q5+BA5+BE5+BI5+BM5+BQ5+BU5+BY5 -> 464 | CL5: =AX5+AT5+AP5+AL5+AH5+AD5+Z5+V5+R5+BB5+BF5+BJ5+BN5+BR5+BV5+BZ5 -> 568 | CM5: =AY5+AU5+AQ5+AM5+AI5+AE5+AA5+W5+S5+BC5+BG5+BK5+BO5+BS5+BW5+CA5 -> 3
A6: 3 | B6: 10.39 | C6: Farrukhabad, Etah and Hardoi Districts | D6: 15000 | E6: 25000 | F6: 30000 | G6: 20 | H6: 18744 | I6: 940 | J6: 30271 | K6: 0 | L6: 1530 | M6: 617 | N6: 495 | P6: 5 | Q6: 5 | R6: 9 | S6: 0 | T6: 1 | U6: 1 | V6: 0 | W6: 0 | X6: 5 | Y6: 3 | Z6: 3 | AA6: 0 | AB6: 16 | AC6: 24 | AD6: 8 | AE6: 0 | AF6: 16 | AG6: 24 | AH6: 8 | AI6: 0 | AJ6: 5 | AK6: 14 | AL6: 9 | AM6: 0 | AN6: 4 | AO6: 3 | AP6: 11 | AQ6: 0 | AR6: 2 | AS6: 2 | AT6: 20 | AU6: 0 | AV6: 5 | AW6: 3 | AX6: 10 | AY6: 0 | AZ6: 6 | BA6: 4 | BB6: 9 | BC6: 0 | BD6: 25 | BE6: 15 | BF6: 12 | BG6: 0 | BH6: 30 | BI6: 10 | BJ6: 21 | BK6: 0 | BL6: 30 | BM6: 10 | BN6: 10 | BO6: 0 | BP6: 27 | BQ6: 10 | BR6: 12 | BS6: 0 | BT6: ='All GAs'!AR6 -> 36 | BU6: ='All GAs'!AS6 -> 15 | BV6: ='All GAs'!AT6 -> 14 | BW6: ='All GAs'!AU6 -> 0 | BX6: ='All GAs'!AV6 -> 18 | BY6: ='All GAs'!AW6 -> 10 | BZ6: ='All GAs'!AX6 -> 14 | CA6: ='All GAs'!AY6 -> 0 | ... CI6: ='All GAs'!BG6 -> 0 | CJ6: =AV6+AR6+AN6+AJ6+AF6+AB6+X6+T6+P6+AZ6+BD6+BH6+BL6+BP6+BT6+BX6 -> 231 | CK6: =AW6+AS6+AO6+AK6+AG6+AC6+Y6+U6+Q6+BA6+BE6+BI6+BM6+BQ6+BU6+BY6 -> 153 | CL6: =AX6+AT6+AP6+AL6+AH6+AD6+Z6+V6+R6+BB6+BF6+BJ6+BN6+BR6+BV6+BZ6 -> 170 | CM6: =AY6+AU6+AQ6+AM6+AI6+AE6+AA6+W6+S6+BC6+BG6+BK6+BO6+BS6+BW6+CA6 -> 0
A7: 4 | B7: 10.48 | C7: Howrah (EAAA) District and Hoogly (EAAA) District | D7: 20000 | E7: 20000 | F7: 40000 | G7: 20 | H7: 8768 | I7: 125 | J7: 14449 | K7: 0 | L7: 2207 | M7: 194 | N7: 1455 | P7: 140 | Q7: 0 | R7: 45 | S7: 0 | T7: 39 | U7: 0 | V7: 43 | W7: 0 | X7: 4 | Y7: 4 | Z7: 39 | AA7: 0 | AB7: 1 | AC7: 10 | AD7: 46 | AE7: 0 | AF7: 1 | AG7: 10 | AH7: 46 | AI7: 0 | AJ7: 14 | AK7: 10 | AL7: 12 | AM7: 0 | AN7: 17 | AO7: 2 | AP7: 22 | AQ7: 0 | AR7: 2 | AS7: 2 | AT7: 32 | AU7: 1 | AV7: 70 | AW7: 6 | AX7: 35 | AY7: 0 | AZ7: 35 | BA7: 6 | BB7: 25 | BC7: 0 | BD7: 27 | BE7: 3 | BF7: 25 | BG7: 0 | BH7: 20 | BI7: 8 | BJ7: 17 | BK7: 0 | BL7: 15 | BM7: 6 | BN7: 25 | BO7: 1 | BP7: 12 | BQ7: 6 | BR7: 17 | BS7: 0 | BT7: ='All GAs'!AR7 -> 22 | BU7: ='All GAs'!AS7 -> 5 | BV7: ='All GAs'!AT7 -> 17 | BW7: ='All GAs'!AU7 -> 0 | BX7: ='All GAs'!AV7 -> 2 | BY7: ='All GAs'!AW7 -> 5 | BZ7: ='All GAs'!AX7 -> 16 | CA7: ='All GAs'!AY7 -> 0 | ... CI7: ='All GAs'!BG7 -> 0 | CJ7: =AV7+AR7+AN7+AJ7+AF7+AB7+X7+T7+P7+AZ7+BD7+BH7+BL7+BP7+BT7+BX7 -> 421 | CK7: =AW7+AS7+AO7+AK7+AG7+AC7+Y7+U7+Q7+BA7+BE7+BI7+BM7+BQ7+BU7+BY7 -> 83 | CL7: =AX7+AT7+AP7+AL7+AH7+AD7+Z7+V7+R7+BB7+BF7+BJ7+BN7+BR7+BV7+BZ7 -> 462 | CM7: =AY7+AU7+AQ7+AM7+AI7+AE7+AA7+W7+S7+BC7+BG7+BK7+BO7+BS7+BW7+CA7 -> 2
A8: 5 | B8: 10.49 | C8: Nadia (EAAA) District and North 24 Parganas (EAAA) District | D8: 15000 | E8: 15000 | F8: 30000 | G8: 10 | H8: 15942 | I8: 349 | J8: 19739 | K8: 0 | L8: 4892 | M8: 495 | N8: 1552 | P8: 27 | Q8: 19 | R8: 38 | S8: 0 | T8: 12 | U8: 14 | V8: 10 | W8: 0 | X8: 9 | Y8: 0 | Z8: 18 | AA8: 0 | AB8: 80 | AC8: 0 | AD8: 55 | AE8: 0 | AF8: 80 | AG8: 0 | AH8: 55 | AI8: 0 | AJ8: 56 | AK8: 8 | AL8: 17 | AM8: 0 | AN8: 10 | AO8: 0 | AP8: 8 | AQ8: 0 | AR8: 1 | AS8: 1 | AT8: 1 | AU8: 1 | AV8: 80 | AW8: 1 | AX8: 8 | AY8: 0 | AZ8: 20 | BA8: 2 | BB8: 9 | BC8: 0 | BD8: 81 | BE8: 5 | BF8: 15 | BG8: 0 | BH8: 39 | BI8: 3 | BJ8: 33 | BK8: 0 | BL8: 40 | BM8: 5 | BN8: 8 | BO8: 1 | BP8: 49 | BQ8: 7 | BR8: 11 | BS8: 6 | BT8: ='All GAs'!AR8 -> 42 | BU8: ='All GAs'!AS8 -> 6 | BV8: ='All GAs'!AT8 -> 12 | BW8: ='All GAs'!AU8 -> 0 | BX8: ='All GAs'!AV8 -> 20 | BY8: ='All GAs'!AW8 -> 11 | BZ8: ='All GAs'!AX8 -> 30 | CA8: ='All GAs'!AY8 -> 0 | ... CI8: ='All GAs'!BG8 -> 0 | CJ8: =AV8+AR8+AN8+AJ8+AF8+AB8+X8+T8+P8+AZ8+BD8+BH8+BL8+BP8+BT8+BX8 -> 646 | CK8: =AW8+AS8+AO8+AK8+AG8+AC8+Y8+U8+Q8+BA8+BE8+BI8+BM8+BQ8+BU8+BY8 -> 82 | CL8: =AX8+AT8+AP8+AL8+AH8+AD8+Z8+V8+R8+BB8+BF8+BJ8+BN8+BR8+BV8+BZ8 -> 328 | CM8: =AY8+AU8+AQ8+AM8+AI8+AE8+AA8+W8+S8+BC8+BG8+BK8+BO8+BS8+BW8+CA8 -> 8
A9: 6 | B9: 10.45 | C9: Shahjahanpur and Budaun Districts | D9: 15000 | E9: 20000 | F9: 30000 | G9: 5 | H9: 19639 | I9: 2884 | J9: 39248 | K9: 4 | L9: 1449 | M9: 453 | N9: 595 | P9: 19 | Q9: 19 | R9: 1 | S9: 0 | T9: 18 | U9: 16 | V9: 0 | W9: 0 | X9: 16 | Y9: 12 | Z9: 0 | AA9: 0 | AB9: 32 | AC9: 26 | AD9: 0 | AE9: 0 | AF9: 32 | AG9: 26 | AH9: 0 | AI9: 0 | AJ9: 0 | AK9: 12 | AL9: 13 | AM9: 0 | AN9: 0 | AO9: 7 | AP9: 0 | AQ9: 0 | AR9: 0 | AS9: 2 | AT9: 0 | AU9: 0 | AV9: 5 | AW9: 6 | AX9: 2 | AY9: 0 | AZ9: 40 | BA9: 12 | BB9: 2 | BC9: 0 | BD9: 40 | BE9: 12 | BF9: 2 | BG9: 0 | BH9: 0 | BI9: 13 | BJ9: 11 | BK9: 0 | BL9: 94 | BM9: 18 | BN9: 0 | BO9: 0 | BP9: 10 | BQ9: 35 | BR9: 0 | BS9: 0 | BT9: ='All GAs'!AR9 -> 53 | BU9: ='All GAs'!AS9 -> 27 | BV9: ='All GAs'!AT9 -> 1 | BW9: ='All GAs'!AU9 -> 0 | BX9: ='All GAs'!AV9 -> 49 | BY9: ='All GAs'!AW9 -> 41 | BZ9: ='All GAs'!AX9 -> 99 | CA9: ='All GAs'!AY9 -> 0 | ... CI9: ='All GAs'!BG9 -> 0 | CJ9: =AV9+AR9+AN9+AJ9+AF9+AB9+X9+T9+P9+AZ9+BD9+BH9+BL9+BP9+BT9+BX9 -> 408 | CK9: =AW9+AS9+AO9+AK9+AG9+AC9+Y9+U9+Q9+BA9+BE9+BI9+BM9+BQ9+BU9+BY9 -> 284 | CL9: =AX9+AT9+AP9+AL9+AH9+AD9+Z9+V9+R9+BB9+BF9+BJ9+BN9+BR9+BV9+BZ9 -> 131 | CM9: =AY9+AU9+AQ9+AM9+AI9+AE9+AA9+W9+S9+BC9+BG9+BK9+BO9+BS9+BW9+CA9 -> 0
A10: 7 | B10: 9.19 | C10: Sonipat District (EAAA) & Jind District | D10: 15000 | E10: 12000 | F10: 30000 | G10: 5 | H10: 14983 | I10: 4198 | J10: 26569 | K10: 2 | L10: 97 | M10: 426 | N10: 18 | P10: 5 | Q10: 22 | R10: 0 | S10: 0 | T10: 0 | U10: 1 | V10: 1 | W10: 0 | X10: 1 | Y10: 4 | Z10: 1 | AA10: 0 | AB10: 7 | AC10: 11 | AD10: 10 | AE10: 0 | AF10: 7 | AG10: 11 | AH10: 10 | AI10: 0 | AJ10: 0 | AK10: 6 | AL10: 0 | AM10: 1 | AN10: 1 | AO10: 8 | AP10: 0 | AQ10: 0 | AR10: 0 | AS10: 3 | AT10: 0 | AU10: 4 | AV10: 7 | AW10: 3 | AX10: 4 | AY10: 1 | AZ10: 4 | BA10: 4 | BB10: 0 | BC10: 0 | BD10: 4 | BE10: 4 | BF10: 0 | BG10: 0 | BH10: 4 | BI10: 5 | BJ10: 0 | BK10: 2 | BL10: 5 | BM10: 10 | BN10: 2 | BO10: 2 | BP10: 7 | BQ10: 5 | BR10: 1 | BS10: 0 | BT10: ='All GAs'!AR10 -> 2 | BU10: ='All GAs'!AS10 -> 11 | BV10: ='All GAs'!AT10 -> 2 | BW10: ='All GAs'!AU10 -> 0 | BX10: ='All GAs'!AV10 -> 0 | BY10: ='All GAs'!AW10 -> 49 | BZ10: ='All GAs'!AX10 -> 6 | CA10: ='All GAs'!AY10 -> 3 | ... CI10: ='All GAs'!BG10 -> 0 | CJ10: =AV10+AR10+AN10+AJ10+AF10+AB10+X10+T10+P10+AZ10+BD10+BH10+BL10+BP10+BT10+BX10 -> 54 | CK10: =AW10+AS10+AO10+AK10+AG10+AC10+Y10+U10+Q10+BA10+BE10+BI10+BM10+BQ10+BU10+BY10 -> 157 | CL10: =AX10+AT10+AP10+AL10+AH10+AD10+Z10+V10+R10+BB10+BF10+BJ10+BN10+BR10+BV10+BZ10 -> 37 | CM10: =AY10+AU10+AQ10+AM10+AI10+AE10+AA10+W10+S10+BC10+BG10+BK10+BO10+BS10+BW10+CA10 -> 13
C11: Total | D11: =SUBTOTAL(9,D4:D10) -> 110000 | E11: =SUBTOTAL(9,E4:E10) -> 132000 | F11: =SUBTOTAL(9,F4:F10) -> 220000 | G11: =SUBTOTAL(9,G4:G10) -> 85 | H11: =SUM(H4:H10) -> 91392 | I11: =SUM(I4:I10) -> 10065 | J11: =SUM(J4:J10) -> 176072 | K11: 7 | L11: =SUM(L4:L10) -> 16574 | M11: =SUM(M4:M10) -> 3849 | N11: =SUM(N4:N10) -> 7255 | P11: =SUM(P4:P10) -> 205 | Q11: =SUM(Q4:Q10) -> 301 | R11: =SUM(R4:R10) -> 128 | S11: 0 | T11: =SUM(T4:T10) -> 149 | U11: =SUM(U4:U10) -> 78 | V11: =SUM(V4:V10) -> 180 | W11: 0 | X11: =SUM(X4:X10) -> 89 | Y11: =SUM(Y4:Y10) -> 57 | Z11: =SUM(Z4:Z10) -> 108 | AA11: 0 | AB11: =SUM(AB4:AB10) -> 234 | AC11: =SUM(AC4:AC10) -> 98 | AD11: =SUM(AD4:AD10) -> 230 | AE11: 0 | AF11: =SUBTOTAL(9,AF4:AF10) -> 234 | AG11: =SUBTOTAL(9,AG4:AG10) -> 98 | AH11: =SUBTOTAL(9,AH4:AH10) -> 230 | AI11: =SUBTOTAL(9,AI4:AI10) -> 0 | AJ11: =SUBTOTAL(9,AJ4:AJ10) -> 146 | AK11: =SUBTOTAL(9,AK4:AK10) -> 60 | AL11: =SUBTOTAL(9,AL4:AL10) -> 67 | AM11: =SUBTOTAL(9,AM4:AM10) -> 2 | ... AQ11: =SUBTOTAL(9,AQ4:AQ10) -> 0 | AR11: =SUM(AR4:AR10) -> 13 | AS11: =SUM(AS4:AS10) -> 23 | AT11: =SUM(AT4:AT10) -> 63 | AU11: =SUM(AU4:AU10) -> 7 | AV11: =SUM(AV4:AV10) -> 282 | AW11: =SUM(AW4:AW10) -> 35 | AX11: =SUM(AX4:AX10) -> 67 | AY11: =SUM(AY4:AY10) -> 1 | ... CM11: =SUM(CM4:CM10) -> 26
A12: Cumm for CGD | H12: 1,57,435 | I12: 12266 | J12: 2,58,070 | K12: 53 (com+ind)
BK14: 10829

Sheet All GAs
A1: GA ID | B1: GA Area | C1: State/UTs | D1: Target PNGRB | H1: PNG Progress - 1st Jan- 22nd Mar'26 | L1: PNG Progress 23rd Mar'26 | P1: PNG Progress 24th Mar'26 | T1: PNG Progress 25th Mar'26 | X1: PNG Progress 26th Mar'26 | AB1: PNG Progress 27th Mar'26 | AF1: PNG Progress 28th Mar'26 | AJ1: PNG Progress 29th Mar'26 | AN1: PNG Progress 30th Mar'26 | AR1: PNG Progress 31st Mar'26 | AV1: PNG Progress 1st April'26 | AZ1: PNG Progress 2nd April'26 | BD1: PNG Progress 3rd April'26 | BH1: PNG Progress Cumm.
D2: LMC | E2: NGC | F2: Registartion | G2: Comm/Ind. | H2: LMC | I2: NGC | J2: Registartion | K2: Comm/Ind. | L2: LMC | M2: NGC | N2: Registartion | O2: Comm/Ind. | P2: LMC | Q2: NGC | R2: Registartion | S2: Comm/Ind. | T2: LMC | U2: NGC | V2: Registartion | W2: Comm/Ind. | X2: LMC | Y2: NGC | Z2: Registartion | AA2: Comm/Ind. | AB2: LMC | AC2: NGC | AD2: Registartion | AE2: Comm/Ind. | AF2: LMC | AG2: NGC | AH2: Registartion | AI2: Comm/Ind. | AJ2: LMC | AK2: NGC | AL2: Registartion | AM2: Comm/Ind. | AN2: LMC | AO2: NGC | AP2: Registartion | AQ2: Comm/Ind. | AR2: LMC | AS2: NGC | AT2: Registartion | AU2: Comm/Ind. | AV2: LMC | AW2: NGC | AX2: Registartion | AY2: Comm/Ind. | AZ2: LMC | BA2: NGC | BB2: Registartion | BC2: Comm/Ind. | BD2: LMC | BE2: NGC | BF2: Registartion | BG2: Comm/Ind. | BH2: LMC | BI2: NGC | BJ2: Registartion | BK2: Comm/Ind.
D3: Nos | E3: Nos. | F3: Nos. | G3: Enrollment | H3: Nos | I3: Nos. | J3: Nos. | K3: Enrollment | L3: Nos | M3: Nos. | N3: Nos. | O3: Enrollment | P3: Nos | Q3: Nos. | R3: Nos. | S3: Enrollment | T3: Nos | U3: Nos. | V3: Nos. | W3: Enrollment | X3: Nos | Y3: Nos. | Z3: Nos. | AA3: Enrollment | AB3: Nos | AC3: Nos. | AD3: Nos. | AE3: Enrollment | AF3: Nos | AG3: Nos. | AH3: Nos. | AI3: Enrollment | AJ3: Nos | AK3: Nos. | AL3: Nos. | AM3: Enrollment | AN3: Nos | AO3: Nos. | AP3: Nos. | AQ3: Enrollment | AR3: Nos | AS3: Nos. | AT3: Nos. | AU3: Enrollment | AV3: Nos | AW3: Nos. | AX3: Nos. | AY3: Enrollment | AZ3: Nos | BA3: Nos. | BB3: Nos. | BC3: Enrollment | BD3: Nos | BE3: Nos. | BF3: Nos. | BG3: Enrollment | BH3: Nos | BI3: Nos. | BJ3: Nos. | BK3: Enrollment
A4: 10.37 | B4: Bareilly, Rampur, Pilibhit | C4: UP | D4: 15000 | E4: 20000 | F4: 30000 | G4: 5 | H4: 894 | I4: 418 | J4: 650 | K4: 0 | L4: 4 | M4: 8 | N4: 5 | O4: 0 | P4: 0 | Q4: 9 | R4: 3 | S4: 0 | T4: ='Focused GAs -MOPNG DATA'!AZ4 -> 0 | U4: ='Focused GAs -MOPNG DATA'!BA4 -> 15 | V4: ='Focused GAs -MOPNG DATA'!BB4 -> 3 | W4: ='Focused GAs -MOPNG DATA'!BC4 -> 0 | X4: ='Focused GAs -MOPNG DATA'!BD4 -> 0 | Y4: ='Focused GAs -MOPNG DATA'!BE4 -> 15 | Z4: ='Focused GAs -MOPNG DATA'!BF4 -> 3 | AA4: ='Focused GAs -MOPNG DATA'!BG4 -> 0 | ... AM4: ='Focused GAs -MOPNG DATA'!BS4 -> 0 | AN4: 10 | AO4: 18 | AP4: 5 | AQ4: 0 | AR4: 10 | AS4: 16 | AT4: 10 | AU4: 0 | AV4: 7 | AW4: 17 | AX4: 10 | AY4: 0 | AZ4: 8 | BA4: 20 | BB4: 5 | BC4: 0 | BD4: 7 | BE4: 14 | BF4: 5 | BG4: 0 | BH4: =L4+P4+X4+AB4+AF4+AN4+AR4+AV4+AZ4 -> 66 | BI4: =M4+Q4+Y4+AC4+AG4+AO4+AS4+AW4+BA4 -> 131 | BJ4: =N4+R4+Z4+AD4+AH4+AP4+AT4+AX4+BB4 -> 49 | BK4: =O4+S4+AA4+AE4+AI4+AQ4+AU4+AY4+BC4 -> 0
A5: 10.47 | B5: Darjeeling, Jalpaiguri & Uttar Dinajpur | C5: WB | D5: 15000 | E5: 20000 | F5: 30000 | G5: 20 | H5: =3113+29 -> 3142 | I5: =544+27 -> 571 | J5: =2694+37 -> 2731 | K5: 1 | L5: 4 | M5: 5 | N5: 5 | O5: 1 | P5: 115 | Q5: 7 | R5: 5 | S5: 0 | T5: ='Focused GAs -MOPNG DATA'!AZ5 -> 3 | U5: ='Focused GAs -MOPNG DATA'!BA5 -> 8 | V5: ='Focused GAs -MOPNG DATA'!BB5 -> 4 | W5: ='Focused GAs -MOPNG DATA'!BC5 -> 0 | X5: ='Focused GAs -MOPNG DATA'!BD5 -> 68 | Y5: ='Focused GAs -MOPNG DATA'!BE5 -> 15 | Z5: ='Focused GAs -MOPNG DATA'!BF5 -> 17 | AA5: ='Focused GAs -MOPNG DATA'!BG5 -> 0 | ... AM5: ='Focused GAs -MOPNG DATA'!BS5 -> 0 | AN5: 43 | AO5: 18 | AP5: 41 | AQ5: 0 | AR5: 71 | AS5: 30 | AT5: 35 | AU5: 0 | AV5: 21 | AW5: 30 | AX5: 34 | AY5: 1 | AZ5: 23 | BA5: 20 | BB5: 30 | BC5: 0 | BD5: 85 | BE5: 28 | BF5: 5 | BG5: 0 | BH5: =L5+P5+X5+AB5+AF5+AN5+AR5+AV5+AZ5 -> 441 | BI5: =M5+Q5+Y5+AC5+AG5+AO5+AS5+AW5+BA5 -> 163 | BJ5: =N5+R5+Z5+AD5+AH5+AP5+AT5+AX5+BB5 -> 201 | BK5: =O5+S5+AA5+AE5+AI5+AQ5+AU5+AY5+BC5 -> 2
A6: 10.39 | B6: Etah, Farrukhabad, Hardoi | C6: UP | D6: 15000 | E6: 25000 | F6: 30000 | G6: 20 | H6: 630 | I6: 134 | J6: 515 | K6: 0 | L6: 2 | M6: 2 | N6: 20 | O6: 0 | P6: 5 | Q6: 3 | R6: 10 | S6: 0 | T6: ='Focused GAs -MOPNG DATA'!AZ6 -> 6 | U6: ='Focused GAs -MOPNG DATA'!BA6 -> 4 | V6: ='Focused GAs -MOPNG DATA'!BB6 -> 9 | W6: ='Focused GAs -MOPNG DATA'!BC6 -> 0 | X6: ='Focused GAs -MOPNG DATA'!BD6 -> 25 | Y6: ='Focused GAs -MOPNG DATA'!BE6 -> 15 | Z6: ='Focused GAs -MOPNG DATA'!BF6 -> 12 | AA6: ='Focused GAs -MOPNG DATA'!BG6 -> 0 | ... AM6: ='Focused GAs -MOPNG DATA'!BS6 -> 0 | AN6: 9 | AO6: 4 | AP6: 15 | AQ6: 0 | AR6: 36 | AS6: 15 | AT6: 14 | AU6: 0 | AV6: 18 | AW6: 10 | AX6: 14 | AY6: 0 | AZ6: 43 | BA6: 10 | BB6: 22 | BC6: 0 | BD6: 16 | BE6: 5 | BF6: 15 | BG6: 0 | BH6: =L6+P6+X6+AB6+AF6+AN6+AR6+AV6+AZ6 -> 198 | BI6: =M6+Q6+Y6+AC6+AG6+AO6+AS6+AW6+BA6 -> 79 | BJ6: =N6+R6+Z6+AD6+AH6+AP6+AT6+AX6+BB6 -> 138 | BK6: =O6+S6+AA6+AE6+AI6+AQ6+AU6+AY6+BC6 -> 0
A7: 10.48 | B7: Howrah & Hooghly | C7: WB | D7: 20000 | E7: 20000 | F7: 40000 | G7: 20 | H7: 1662 | I7: 98 | J7: 1519 | K7: 1 | L7: 2 | M7: 2 | N7: 32 | O7: 0 | P7: 70 | Q7: 6 | R7: 35 | S7: 0 | T7: ='Focused GAs -MOPNG DATA'!AZ7 -> 35 | U7: ='Focused GAs -MOPNG DATA'!BA7 -> 6 | V7: ='Focused GAs -MOPNG DATA'!BB7 -> 25 | W7: ='Focused GAs -MOPNG DATA'!BC7 -> 0 | X7: ='Focused GAs -MOPNG DATA'!BD7 -> 27 | Y7: ='Focused GAs -MOPNG DATA'!BE7 -> 3 | Z7: ='Focused GAs -MOPNG DATA'!BF7 -> 25 | AA7: ='Focused GAs -MOPNG DATA'!BG7 -> 0 | ... AM7: ='Focused GAs -MOPNG DATA'!BS7 -> 0 | AN7: 13 | AO7: 5 | AP7: 12 | AQ7: 0 | AR7: 22 | AS7: 5 | AT7: 17 | AU7: 0 | AV7: 2 | AW7: 5 | AX7: 16 | AY7: 0 | AZ7: 21 | BA7: 4 | BB7: 27 | BC7: 0 | BD7: 19 | BE7: 4 | BF7: 25 | BG7: 0 | BH7: =L7+P7+X7+AB7+AF7+AN7+AR7+AV7+AZ7 -> 192 | BI7: =M7+Q7+Y7+AC7+AG7+AO7+AS7+AW7+BA7 -> 44 | BJ7: =N7+R7+Z7+AD7+AH7+AP7+AT7+AX7+BB7 -> 206 | BK7: =O7+S7+AA7+AE7+AI7+AQ7+AU7+AY7+BC7 -> 1
A8: 10.49 | B8: Nadia & North 24 Parganas | C8: WB | D8: 15000 | E8: 15000 | F8: 30000 | G8: 10 | H8: 4209 | I8: 149 | J8: 1455 | K8: 0 | L8: 1 | M8: 1 | N8: 1 | O8: 1 | P8: 80 | Q8: 1 | R8: 8 | S8: 0 | T8: ='Focused GAs -MOPNG DATA'!AZ8 -> 20 | U8: ='Focused GAs -MOPNG DATA'!BA8 -> 2 | V8: ='Focused GAs -MOPNG DATA'!BB8 -> 9 | W8: ='Focused GAs -MOPNG DATA'!BC8 -> 0 | X8: ='Focused GAs -MOPNG DATA'!BD8 -> 81 | Y8: ='Focused GAs -MOPNG DATA'!BE8 -> 5 | Z8: ='Focused GAs -MOPNG DATA'!BF8 -> 15 | AA8: ='Focused GAs -MOPNG DATA'!BG8 -> 0 | ... AM8: ='Focused GAs -MOPNG DATA'!BS8 -> 6 | AN8: 36 | AO8: 6 | AP8: 9 | AQ8: 0 | AR8: 42 | AS8: 6 | AT8: 12 | AU8: 0 | AV8: 20 | AW8: 11 | AX8: 30 | AY8: 0 | AZ8: 78 | BA8: 14 | BB8: 20 | BC8: 0 | BD8: 10 | BE8: 15 | BF8: 7 | BG8: 0 | BH8: =L8+P8+X8+AB8+AF8+AN8+AR8+AV8+AZ8 -> 417 | BI8: =M8+Q8+Y8+AC8+AG8+AO8+AS8+AW8+BA8 -> 52 | BJ8: =N8+R8+Z8+AD8+AH8+AP8+AT8+AX8+BB8 -> 136 | BK8: =O8+S8+AA8+AE8+AI8+AQ8+AU8+AY8+BC8 -> 2
A9: 10.45 | B9: Shahjahanpur Badaun | C9: UP | D9: 15000 | E9: 20000 | F9: 30000 | G9: 5 | H9: =813-38 -> 775 | I9: =365+7 -> 372 | J9: =624-3 -> 621 | K9: 0 | L9: 0 | M9: 2 | N9: 0 | O9: 0 | P9: 5 | Q9: 6 | R9: 2 | S9: 0 | T9: ='Focused GAs -MOPNG DATA'!AZ9 -> 40 | U9: ='Focused GAs -MOPNG DATA'!BA9 -> 12 | V9: ='Focused GAs -MOPNG DATA'!BB9 -> 2 | W9: ='Focused GAs -MOPNG DATA'!BC9 -> 0 | X9: ='Focused GAs -MOPNG DATA'!BD9 -> 40 | Y9: ='Focused GAs -MOPNG DATA'!BE9 -> 12 | Z9: ='Focused GAs -MOPNG DATA'!BF9 -> 2 | AA9: ='Focused GAs -MOPNG DATA'!BG9 -> 0 | ... AM9: ='Focused GAs -MOPNG DATA'!BS9 -> 0 | AN9: 53 | AO9: 27 | AP9: 1 | AQ9: 0 | AR9: 53 | AS9: 27 | AT9: 1 | AU9: 0 | AV9: 49 | AW9: 41 | AX9: 99 | AY9: 0 | AZ9: 16 | BA9: 7 | BB9: 0 | BC9: 0 | BD9: 42 | BE9: 7 | BF9: 0 | BG9: 0 | BH9: =L9+P9+X9+AB9+AF9+AN9+AR9+AV9+AZ9 -> 310 | BI9: =M9+Q9+Y9+AC9+AG9+AO9+AS9+AW9+BA9 -> 153 | BJ9: =N9+R9+Z9+AD9+AH9+AP9+AT9+AX9+BB9 -> 116 | BK9: =O9+S9+AA9+AE9+AI9+AQ9+AU9+AY9+BC9 -> 0
A10: 9.19 | B10: Sonipat - Jind GA | C10: Haryana | D10: 15000 | E10: 12000 | F10: 30000 | G10: 5 | H10: =105+15 -> 120 | I10: =217+18 -> 235 | J10: =48+7 -> 55 | K10: 3 | L10: 0 | M10: 3 | N10: 0 | O10: 2 | P10: 7 | Q10: 3 | R10: 4 | S10: 1 | T10: ='Focused GAs -MOPNG DATA'!AZ10 -> 4 | U10: ='Focused GAs -MOPNG DATA'!BA10 -> 4 | V10: ='Focused GAs -MOPNG DATA'!BB10 -> 0 | W10: ='Focused GAs -MOPNG DATA'!BC10 -> 0 | X10: ='Focused GAs -MOPNG DATA'!BD10 -> 4 | Y10: ='Focused GAs -MOPNG DATA'!BE10 -> 4 | Z10: ='Focused GAs -MOPNG DATA'!BF10 -> 0 | AA10: ='Focused GAs -MOPNG DATA'!BG10 -> 0 | ... AM10: ='Focused GAs -MOPNG DATA'!BS10 -> 0 | AN10: 4 | AO10: 6 | AP10: 0 | AQ10: 0 | AR10: 2 | AS10: 11 | AT10: 2 | AU10: 0 | AV10: 0 | AW10: 49 | AX10: 6 | AY10: 3 | AZ10: 0 | BA10: 10 | BB10: 4 | BC10: 0 | BD10: 2 | BE10: 10 | BF10: 0 | BG10: 0 | BH10: =L10+P10+X10+AB10+AF10+AN10+AR10+AV10+AZ10 -> 26 | BI10: =M10+Q10+Y10+AC10+AG10+AO10+AS10+AW10+BA10 -> 101 | BJ10: =N10+R10+Z10+AD10+AH10+AP10+AT10+AX10+BB10 -> 18 | BK10: =O10+S10+AA10+AE10+AI10+AQ10+AU10+AY10+BC10 -> 10
A11: 10.43 | B11: Mainpuri Kannauj | C11: UP | D11: 10000 | E11: 5000 | F11: 20000 | G11: 8 | H11: 960 | I11: 423 | J11: 665 | K11: 1 | L11: 9 | M11: 8 | N11: 8 | O11: 0 | P11: 10 | Q11: 13 | R11: 10 | S11: 0 | T11: 10 | U11: 20 | V11: 4 | W11: 0 | X11: 10 | Y11: 20 | Z11: 4 | AA11: 0 | AB11: 8 | AC11: 20 | AD11: 4 | AE11: 0 | AF11: 10 | AG11: 14 | AH11: 3 | AI11: 0 | AJ11: 10 | AK11: 20 | AL11: 6 | AM11: 0 | AN11: 10 | AO11: 18 | AP11: 8 | AQ11: 0 | AR11: 10 | AS11: 30 | AT11: 5 | AU11: 0 | AV11: 8 | AW11: 32 | AX11: 6 | AY11: 0 | AZ11: 6 | BA11: 15 | BB11: 2 | BC11: 0 | BD11: 7 | BE11: 9 | BF11: 6 | BG11: 0 | BH11: =L11+P11+X11+AB11+AF11+AN11+AR11+AV11+AZ11 -> 81 | BI11: =M11+Q11+Y11+AC11+AG11+AO11+AS11+AW11+BA11 -> 170 | BJ11: =N11+R11+Z11+AD11+AH11+AP11+AT11+AX11+BB11 -> 50 | BK11: =O11+S11+AA11+AE11+AI11+AQ11+AU11+AY11+BC11 -> 0
A12: 10.46 | B12: Nainital Bijnor | C12: UK/UP | D12: 10000 | E12: 5000 | F12: 20000 | G12: 8 | H12: 483 | I12: 429 | J12: 104 | K12: 0 | L12: 5 | M12: 0 | N12: 24 | O12: 0 | P12: 2 | Q12: 0 | R12: 18 | S12: 0 | T12: 2 | U12: 3 | V12: 4 | W12: 0 | X12: 5 | Y12: 8 | Z12: 15 | AA12: 0 | AB12: 5 | AC12: 14 | AD12: 12 | AE12: 0 | AF12: 11 | AG12: 15 | AH12: 15 | AI12: 0 | AJ12: 16 | AK12: 25 | AL12: 8 | AM12: 0 | AN12: 5 | AO12: 19 | AP12: 5 | AQ12: 0 | AR12: 15 | AS12: 24 | AT12: 22 | AU12: 0 | AV12: 10 | AW12: 19 | AX12: 25 | AY12: 0 | AZ12: 10 | BA12: 17 | BB12: 0 | BC12: 0 | BD12: 15 | BE12: 16 | BF12: 0 | BG12: 0 | BH12: =L12+P12+X12+AB12+AF12+AN12+AR12+AV12+AZ12 -> 68 | BI12: =M12+Q12+Y12+AC12+AG12+AO12+AS12+AW12+BA12 -> 116 | BJ12: =N12+R12+Z12+AD12+AH12+AP12+AT12+AX12+BB12 -> 136 | BK12: =O12+S12+AA12+AE12+AI12+AQ12+AU12+AY12+BC12 -> 0
A13: 10.5 | B13: South 24 Parganas | C13: WB | D13: 10000 | E13: 5000 | F13: 20000 | G13: 8 | H13: 700 | I13: 28 | J13: 438 | K13: 0 | L13: 7 | M13: 1 | N13: 5 | O13: 0 | P13: 8 | Q13: 0 | R13: 2 | S13: 0 | T13: 6 | U13: 0 | V13: 8 | W13: 0 | X13: 6 | Y13: 0 | Z13: 8 | AA13: 0 | AB13: 2 | AC13: 0 | AD13: 5 | AE13: 0 | AF13: 2 | AG13: 3 | AH13: 1 | AI13: 0 | AJ13: 2 | AK13: 2 | AL13: 9 | AM13: 0 | AN13: 1 | AO13: 9 | AP13: 1 | AQ13: 0 | AR13: 2 | AS13: 2 | AT13: 10 | AU13: 0 | AV13: 2 | AW13: 2 | AX13: 9 | AY13: 0 | AZ13: 4 | BA13: 0 | BB13: 2 | BC13: 0 | BD13: 7 | BE13: 1 | BF13: 10 | BG13: 0 | BH13: =L13+P13+X13+AB13+AF13+AN13+AR13+AV13+AZ13 -> 34 | BI13: =M13+Q13+Y13+AC13+AG13+AO13+AS13+AW13+BA13 -> 17 | BJ13: =N13+R13+Z13+AD13+AH13+AP13+AT13+AX13+BB13 -> 43 | BK13: =O13+S13+AA13+AE13+AI13+AQ13+AU13+AY13+BC13 -> 0
A14: 11.44 | B14: Dausa, Karauli, Sawai Madhopur & Tonk | C14: RJ | D14: 10000 | E14: 5000 | F14: 20000 | G14: 5 | H14: 1853 | I14: 34 | J14: 1933 | K14: 0 | L14: 24 | M14: 2 | N14: 22 | O14: 0 | P14: 22 | Q14: 3 | R14: 20 | S14: 0 | T14: 10 | U14: 5 | V14: 12 | W14: 0 | X14: 20 | Y14: 2 | Z14: 18 | AA14: 0 | AB14: 18 | AC14: 4 | AD14: 19 | AE14: 0 | AF14: 22 | AG14: 5 | AH14: 16 | AI14: 0 | AJ14: 19 | AK14: 8 | AL14: 17 | AM14: 0 | AN14: 10 | AO14: 6 | AP14: 12 | AQ14: 0 | AR14: 19 | AS14: 7 | AT14: 17 | AU14: 0 | AV14: 17 | AW14: 11 | AX14: 19 | AY14: 0 | AZ14: 20 | BA14: 6 | BB14: 12 | BC14: 0 | BD14: 19 | BE14: 6 | BF14: 18 | BG14: 0 | BH14: =L14+P14+X14+AB14+AF14+AN14+AR14+AV14+AZ14 -> 172 | BI14: =M14+Q14+Y14+AC14+AG14+AO14+AS14+AW14+BA14 -> 46 | BJ14: =N14+R14+Z14+AD14+AH14+AP14+AT14+AX14+BB14 -> 155 | BK14: =O14+S14+AA14+AE14+AI14+AQ14+AU14+AY14+BC14 -> 0
A15: 11A.02 | B15: Banka, Dumka, Godda. Jamtara, Pakur & Sahibganj | C15: Bihar/Jharkhand | D15: 10000 | E15: 5000 | F15: 20000 | G15: 0 | H15: 1069 | I15: 0 | J15: 1135 | K15: 0 | L15: 8 | M15: 0 | N15: 5 | O15: 0 | P15: 9 | Q15: 0 | R15: 30 | S15: 0 | T15: 7 | U15: 0 | V15: 10 | W15: 0 | X15: 10 | Y15: 0 | Z15: 17 | AA15: 0 | AB15: 11 | AC15: 0 | AD15: 12 | AE15: 0 | AF15: 7 | AG15: 0 | AH15: 7 | AI15: 0 | AJ15: 11 | AK15: 0 | AL15: 10 | AM15: 0 | AN15: 8 | AO15: 0 | AP15: 11 | AQ15: 0 | AR15: 10 | AS15: 0 | AT15: 13 | AU15: 0 | AV15: 15 | AW15: 0 | AX15: 10 | AY15: 0 | AZ15: 13 | BA15: 13 | BB15: 13 | BC15: 13 | BD15: 9 | BE15: 0 | BF15: 13 | BG15: 0 | BH15: =L15+P15+X15+AB15+AF15+AN15+AR15+AV15+AZ15 -> 91 | BI15: =M15+Q15+Y15+AC15+AG15+AO15+AS15+AW15+BA15 -> 13 | BJ15: =N15+R15+Z15+AD15+AH15+AP15+AT15+AX15+BB15 -> 118 | BK15: =O15+S15+AA15+AE15+AI15+AQ15+AU15+AY15+BC15 -> 13
A16: 11A.03 | B16: Birbhum, Mursiddabad, Maldah | C16: WB | D16: 10000 | E16: 5000 | F16: 20000 | G16: 5 | H16: 854 | I16: 0 | J16: 1877 | K16: 0 | L16: 20 | M16: 0 | N16: 13 | O16: 0 | P16: 20 | Q16: 0 | R16: 13 | S16: 0 | T16: 15 | U16: 0 | V16: 12 | W16: 0 | X16: 21 | Y16: 0 | Z16: 15 | AA16: 0 | AB16: 21 | AC16: 0 | AD16: 20 | AE16: 0 | AF16: 12 | AG16: 0 | AH16: 13 | AI16: 0 | AJ16: 16 | AK16: 0 | AL16: 21 | AM16: 0 | AN16: 20 | AO16: 0 | AP16: 14 | AQ16: 0 | AR16: 27 | AS16: 0 | AT16: 25 | AU16: 0 | AV16: 29 | AW16: 0 | AX16: 31 | AY16: 0 | AZ16: 22 | BA16: 0 | BB16: 26 | BC16: 0 | BD16: 25 | BE16: 0 | BF16: 23 | BG16: 0 | BH16: =L16+P16+X16+AB16+AF16+AN16+AR16+AV16+AZ16 -> 192 | BI16: =M16+Q16+Y16+AC16+AG16+AO16+AS16+AW16+BA16 -> 0 | BJ16: =N16+R16+Z16+AD16+AH16+AP16+AT16+AX16+BB16 -> 170 | BK16: =O16+S16+AA16+AE16+AI16+AQ16+AU16+AY16+BC16 -> 0
A17: 12.05 | B17: Sikkim | C17: Sikkim | D17: 0 | E17: 0 | F17: 0 | G17: 0 | H17: 0 | I17: 0 | J17: 0 | K17: 0 | L17: 0 | M17: 0 | N17: 0 | O17: 0 | P17: 0 | Q17: 0 | R17: 0 | S17: 0 | T17: 0 | U17: 0 | V17: 0 | W17: 0 | X17: 0 | Y17: 0 | Z17: 0 | AA17: 0 | AB17: 0 | AC17: 0 | AD17: 0 | AE17: 0 | AF17: 0 | AG17: 0 | AH17: 0 | AI17: 0 | AJ17: 0 | AK17: 0 | AL17: 0 | AM17: 0 | AN17: 0 | AO17: 0 | AP17: 0 | AQ17: 0 | AR17: 0 | AS17: 0 | AT17: 0 | AU17: 0 | AV17: 0 | AW17: 0 | AX17: 0 | AY17: 0 | AZ17: 0 | BA17: 0 | BB17: 0 | BC17: 0 | BD17: 0 | BE17: 0 | BF17: 0 | BG17: 0 | BH17: =L17+P17+X17+AB17+AF17+AN17+AR17+AV17+AZ17 -> 0 | BI17: =M17+Q17+Y17+AC17+AG17+AO17+AS17+AW17+BA17 -> 0 | BJ17: =N17+R17+Z17+AD17+AH17+AP17+AT17+AX17+BB17 -> 0 | BK17: =O17+S17+AA17+AE17+AI17+AQ17+AU17+AY17+BC17 -> 0
B18: Total | D18: =SUM(D4:D17) -> 170000 | E18: =SUM(E4:E17) -> 162000 | F18: =SUM(F4:F17) -> 340000 | G18: =SUM(G4:G17) -> 119 | H18: =SUM(H4:H17) -> 17351 | I18: =SUM(I4:I17) -> 2891 | J18: =SUM(J4:J17) -> 13698 | K18: =SUM(K4:K17) -> 6 | ... BK18: =SUM(BK4:BK17) -> 28
BI20: 16555
BI22: 10829 | BJ22: 3406 | BK22: 2349

Sheet MIS Summary
B2: Summary | E2: Cum. MARCH-26 | G2: 1st April | I2: 2nd April | K2: 3rd April | M2: 4th April | O2: Cumulative April'26 | Q2: Cumulative NGC
B3: Entity Name | E3: New Connection Done & Gasified | F3: Old Connection Done & Gasified | G3: New Connection Done & Gasified | H3: Old Connection Done & Gasified | I3: New Connection Done & Gasified | J3: Old Connection Done & Gasified | K3: New Connection Done & Gasified | L3: Old Connection Done & Gasified | M3: New Connection Done & Gasified | N3: Old Connection Done & Gasified | O3: New Connection Done & Gasified | P3: Old Connection Done & Gasified | Q3: New Connection Done & Gasified | R3: Old Connection Done & Gasified | S3: Grand total NGC
B6: HPCL | E6: ='HPCL-JV MIS'!D17 -> 2366 | F6: ='HPCL-JV MIS'!E17 -> 2022 | G6: ='HPCL-JV MIS'!F17 -> 154 | H6: ='HPCL-JV MIS'!G17 -> 227 | I6: ='HPCL-JV MIS'!H17 -> 229 | J6: ='HPCL-JV MIS'!I17 -> 123 | K6: ='HPCL-JV MIS'!J17 -> 229 | L6: ='HPCL-JV MIS'!K17 -> 115 | ... N6: ='HPCL-JV MIS'!M17 -> 104 | O6: =G6+I6+K6+M6 -> 801 | P6: =H6+J6+L6+N6 -> 569 | Q6: =E6+O6 -> 3167 | R6: =F6+P6 -> 2591 | S6: =Q6+R6 -> 5758
B7: HOGPL | E7: ='HPCL-JV MIS'!D26 -> 84 | F7: ='HPCL-JV MIS'!E26 -> 475 | G7: ='HPCL-JV MIS'!F26 -> 12 | H7: ='HPCL-JV MIS'!G26 -> 18 | I7: ='HPCL-JV MIS'!H26 -> 1 | J7: ='HPCL-JV MIS'!I26 -> 36 | K7: ='HPCL-JV MIS'!J26 -> 0 | L7: ='HPCL-JV MIS'!K26 -> 27 | ... N7: ='HPCL-JV MIS'!M26 -> 74 | O7: =G7+I7+K7+M7 -> 15 | P7: =H7+J7+L7+N7 -> 155 | Q7: =E7+O7 -> 99 | R7: =F7+P7 -> 630 | S7: =Q7+R7 -> 729
B8: BGL | E8: ='HPCL-JV MIS'!D36 -> 212 | F8: ='HPCL-JV MIS'!E36 -> 508 | G8: ='HPCL-JV MIS'!F36 -> 0 | H8: ='HPCL-JV MIS'!G36 -> 43 | I8: ='HPCL-JV MIS'!H36 -> 1 | J8: ='HPCL-JV MIS'!I36 -> 38 | K8: ='HPCL-JV MIS'!J36 -> 2 | L8: ='HPCL-JV MIS'!K36 -> 60 | ... N8: ='HPCL-JV MIS'!M36 -> 39 | O8: =G8+I8+K8+M8 -> 5 | P8: =H8+J8+L8+N8 -> 180 | Q8: =E8+O8 -> 217 | R8: =F8+P8 -> 688 | S8: =Q8+R8 -> 905
B9: Total | E9: =SUM(E6:E8) -> 2662 | F9: =SUM(F6:F8) -> 3005 | G9: =SUM(G6:G8) -> 166 | H9: =SUM(H6:H8) -> 288 | I9: =SUM(I6:I8) -> 231 | J9: =SUM(J6:J8) -> 197 | K9: =SUM(K6:K8) -> 231 | L9: =SUM(L6:L8) -> 202 | ... S9: =SUM(S6:S8) -> 7392
B10: Grand Total | E10: =E9+F9 -> 5667 | G10: =G9+H9 -> 454 | I10: =I9+J9 -> 428 | K10: =K9+L9 -> 433 | M10: =M9+N9 -> 410 | O10: =O9+P9 -> 1725 | Q10: =Q9+R9 -> 7392

Sheet HPCL-JV MIS
A1: NGC Progress MIS – Gasified Geographical Area (HPCL & JVs)
A2: HPCL | D2: Cum MARCH-26 | F2: 1st April | H2: 2nd April | J2: 3rd April | L2: 4th April | N2: Cumulative April'26 | P2: Cumulative NGC
A3: GA ID | B3: GA Area | C3: State/UTs | D3: New Connection Done & Gasified | E3: Old Connection Done & Gasified | F3: New Connection Done & Gasified | G3: Old Connection Done & Gasified | H3: New Connection Done & Gasified | I3: Old Connection Done & Gasified | J3: New Connection Done & Gasified | K3: Old Connection Done & Gasified | L3: New Connection Done & Gasified | M3: Old Connection Done & Gasified | N3: New Connection Done & Gasified | O3: Old Connection Done & Gasified | P3: New Connection Done & Gasified | Q3: Old Connection Done & Gasified | R3: Grand total NGC
A6: 10.37 | B6: Bareilly, Rampur, Pilibhit | C6: UP | D6: 84 | E6: 233 | F6: 7 | G6: 17 | H6: 8 | I6: 20 | J6: 7 | K6: 14 | L6: 10 | M6: 24 | N6: =F6+H6+J6+L6 -> 32 | O6: =G6+I6+K6+M6 -> 75 | P6: =D6+N6 -> 116 | Q6: =E6+O6 -> 308 | R6: =P6+Q6 -> 424
A7: 10.47 | B7: Darjeeling, Jalpaiguri & Uttar Dinajpur | C7: WB | D7: 688 | E7: 546 | F7: 21 | G7: 30 | H7: 23 | I7: 20 | J7: 85 | K7: 28 | L7: 79 | M7: 21 | N7: =F7+H7+J7+L7 -> 208 | O7: =G7+I7+K7+M7 -> 99 | P7: =D7+N7 -> 896 | Q7: =E7+O7 -> 645 | R7: =P7+Q7 -> 1541
A8: 10.39 | B8: Etah, Farrukhabad, Hardoi | C8: UP | D8: 231 | E8: 141 | F8: 18 | G8: 10 | H8: 43 | I8: 10 | J8: 16 | K8: 5 | L8: 14 | M8: 6 | N8: =F8+H8+J8+L8 -> 91 | O8: =G8+I8+K8+M8 -> 31 | P8: =D8+N8 -> 322 | Q8: =E8+O8 -> 172 | R8: =P8+Q8 -> 494
A9: 10.48 | B9: Howrah & Hooghly | C9: WB | D9: 421 | E9: 56 | F9: 2 | G9: 5 | H9: 21 | I9: 4 | J9: 19 | K9: 4 | L9: 21 | M9: 4 | N9: =F9+H9+J9+L9 -> 63 | O9: =G9+I9+K9+M9 -> 17 | P9: =D9+N9 -> 484 | Q9: =E9+O9 -> 73 | R9: =P9+Q9 -> 557
A10: 10.49 | B10: Nadia & North 24 Parganas | C10: WB | D10: 400 | E10: 137 | F10: 20 | G10: 11 | H10: 78 | I10: 14 | J10: 10 | K10: 15 | L10: 4 | M10: 10 | N10: =F10+H10+J10+L10 -> 112 | O10: =G10+I10+K10+M10 -> 50 | P10: =D10+N10 -> 512 | Q10: =E10+O10 -> 187 | R10: =P10+Q10 -> 699
A11: 10.45 | B11: Shahjahanpur Badaun | C11: UP | D11: 408 | E11: 296 | F11: 49 | G11: 41 | H11: 16 | I11: 7 | J11: 42 | K11: 7 | L11: 25 | M11: 7 | N11: =F11+H11+J11+L11 -> 132 | O11: =G11+I11+K11+M11 -> 62 | P11: =D11+N11 -> 540 | Q11: =E11+O11 -> 358 | R11: =P11+Q11 -> 898
A12: 9.19 | B12: Sonipat - Jind GA | C12: Haryana | D12: 54 | E12: 193 | F12: 0 | G12: 49 | H12: 0 | I12: 10 | J12: 2 | K12: 10 | L12: 0 | M12: 0 | N12: =F12+H12+J12+L12 -> 2 | O12: =G12+I12+K12+M12 -> 69 | P12: =D12+N12 -> 56 | Q12: =E12+O12 -> 262 | R12: =P12+Q12 -> 318
A13: 10.43 | B13: Mainpuri Kannauj | C13: UP | D13: 20 | E13: 232 | F13: 8 | G13: 32 | H13: 6 | I13: 15 | J13: 7 | K13: 9 | L13: 6 | M13: 9 | N13: =F13+H13+J13+L13 -> 27 | O13: =G13+I13+K13+M13 -> 65 | P13: =D13+N13 -> 47 | Q13: =E13+O13 -> 297 | R13: =P13+Q13 -> 344
A14: 10.46 | B14: Nainital Bijnor | C14: UK/UP | D14: 5 | E14: 167 | F14: 10 | G14: 19 | H14: 10 | I14: 17 | J14: 15 | K14: 16 | L14: 8 | M14: 15 | N14: =F14+H14+J14+L14 -> 43 | O14: =G14+I14+K14+M14 -> 67 | P14: =D14+N14 -> 48 | Q14: =E14+O14 -> 234 | R14: =P14+Q14 -> 282
A15: 10.5 | B15: South 24 Parganas | C15: WB | D15: 3 | E15: 21 | F15: 2 | G15: 2 | H15: 4 | I15: 0 | J15: 7 | K15: 1 | L15: 5 | M15: 0 | N15: =F15+H15+J15+L15 -> 18 | O15: =G15+I15+K15+M15 -> 3 | P15: =D15+N15 -> 21 | Q15: =E15+O15 -> 24 | R15: =P15+Q15 -> 45
A16: 11.44 | B16: Dausa, Karauli, Sawai Madhopur & Tonk | C16: RJ | D16: 52 | E16: 0 | F16: 17 | G16: 11 | H16: 20 | I16: 6 | J16: 19 | K16: 6 | L16: 17 | M16: 8 | N16: =F16+H16+J16+L16 -> 73 | O16: =G16+I16+K16+M16 -> 31 | P16: =D16+N16 -> 125 | Q16: =E16+O16 -> 31 | R16: =P16+Q16 -> 156
A17: Total | D17: =SUM(D6:D16) -> 2366 | E17: =SUM(E6:E16) -> 2022 | F17: =SUM(F6:F16) -> 154 | G17: =SUM(G6:G16) -> 227 | H17: =SUM(H6:H16) -> 229 | I17: =SUM(I6:I16) -> 123 | J17: =SUM(J6:J16) -> 229 | K17: =SUM(K6:K16) -> 115 | ... R17: =SUM(R6:R16) -> 5758
A18: Grand Total | D18: =D17+E17 -> 4388 | F18: =F17+G17 -> 381 | H18: =H17+I17 -> 352 | J18: =J17+K17 -> 344 | L18: =L17+M17 -> 293 | N18: =N17+O17 -> 1370 | P18: =P17+Q17 -> 5758
A20: HOGPL | D20: Cum MARCH-26 | F20: 1st April | H20: 2nd April | J20: 3rd April | L20: 4th April | N20: Cumulative April'26 | P20: Cumulative NGC
A21: GA ID | B21: GA Area | C21: State/UTs | D21: New Connection Done & Gasified | E21: Old Connection Done & Gasified | F21: New Connection Done & Gasified | G21: Old Connection Done & Gasified | H21: New Connection Done & Gasified | I21: Old Connection Done & Gasified | J21: New Connection Done & Gasified | K21: Old Connection Done & Gasified | L21: New Connection Done & Gasified | M21: Old Connection Done & Gasified | N21: New Connection Done & Gasified | O21: Old Connection Done & Gasified | P21: New Connection Done & Gasified | Q21: Old Connection Done & Gasified | R21: Grand total NGC
A24: 8.03 | B24: Ambala & Kurukshetra Districts | C24: Haryana | D24: 74 | E24: 251 | F24: 12 | G24: 7 | H24: 1 | I24: 21 | J24: 0 | K24: 19 | L24: 2 | M24: 39 | N24: =F24+H24+J24+L24 -> 15 | O24: =G24+I24+K24+M24 -> 86 | P24: =D24+N24 -> 89 | Q24: =E24+O24 -> 337 | R24: =P24+Q24 -> 426
A25: 8.04 | B25: Kolhapur District | C25: Maharashtra | D25: 10 | E25: 224 | F25: 0 | G25: 11 | H25: 0 | I25: 15 | J25: 0 | K25: 8 | L25: 0 | M25: 35 | N25: =F25+H25+J25+L25 -> 0 | O25: =G25+I25+K25+M25 -> 69 | P25: =D25+N25 -> 10 | Q25: =E25+O25 -> 293 | R25: =P25+Q25 -> 303
A26: Total | D26: =SUM(D24:D25) -> 84 | E26: =SUM(E24:E25) -> 475 | F26: =SUM(F24:F25) -> 12 | G26: =SUM(G24:G25) -> 18 | H26: =SUM(H24:H25) -> 1 | I26: =SUM(I24:I25) -> 36 | J26: =SUM(J24:J25) -> 0 | K26: =SUM(K24:K25) -> 27 | ... Q26: =SUM(Q24:Q25) -> 630 | R26: =P26+Q26 -> 729
A27: Grand Total | D27: =D26+E26 -> 559 | F27: =F26+G26 -> 30 | H27: =H26+I26 -> 37 | J27: =J26+K26 -> 27 | L27: =L26+M26 -> 76 | N27: =N26+O26 -> 170 | P27: =P26+Q26 -> 729
A29: BGL | D29: Cum MARCH-26 | F29: 1st April | H29: 2nd April | J29: 3rd April | L29: 4th April | N29: Cumulative April'26 | P29: Cumulative NGC
A30: GA ID | B30: GA Area | C30: State/UTs | D30: New Connection Done & Gasified | E30: Old Connection Done & Gasified | F30: New Connection Done & Gasified | G30: Old Connection Done & Gasified | H30: New Connection Done & Gasified | I30: Old Connection Done & Gasified | J30: New Connection Done & Gasified | K30: Old Connection Done & Gasified | L30: New Connection Done & Gasified | M30: Old Connection Done & Gasified | N30: New Connection Done & Gasified | O30: Old Connection Done & Gasified | P30: New Connection Done & Gasified | Q30: Old Connection Done & Gasified | R30: Grand total NGC
A33: 99.09 | B33: Hyderabad | C33: Telangana | D33: 192 | E33: 261 | F33: 0 | G33: 30 | H33: 0 | I33: 23 | J33: 0 | K33: 39 | L33: 0 | M33: 23 | N33: =F33+H33+J33+L33 -> 0 | O33: =G33+I33+K33+M33 -> 115 | P33: =D33+N33 -> 192 | Q33: =E33+O33 -> 376 | R33: =P33+Q33 -> 568
A34: 1.04 | B34: Kakinada | C34: Andhra Pradesh | D34: 5 | E34: 107 | F34: 0 | G34: 8 | H34: 1 | I34: 8 | J34: 2 | K34: 9 | L34: 2 | M34: 7 | N34: =F34+H34+J34+L34 -> 5 | O34: =G34+I34+K34+M34 -> 32 | P34: =D34+N34 -> 10 | Q34: =E34+O34 -> 139 | R34: =P34+Q34 -> 149
A35: 99.06 | B35: Vijaywada | C35: Andhra Pradesh | D35: 15 | E35: 140 | F35: 0 | G35: 5 | H35: 0 | I35: 7 | J35: 0 | K35: 12 | L35: 0 | M35: 9 | N35: =F35+H35+J35+L35 -> 0 | O35: =G35+I35+K35+M35 -> 33 | P35: =D35+N35 -> 15 | Q35: =E35+O35 -> 173 | R35: =P35+Q35 -> 188
A36: Total | D36: =SUM(D33:D35) -> 212 | E36: =SUM(E33:E35) -> 508 | F36: =SUM(F33:F35) -> 0 | G36: =SUM(G33:G35) -> 43 | H36: =SUM(H33:H35) -> 1 | I36: =SUM(I33:I35) -> 38 | J36: =SUM(J33:J35) -> 2 | K36: =SUM(K33:K35) -> 60 | ... R36: =SUM(R33:R35) -> 905
A37: Grand Total | D37: =D36+E36 -> 720 | F37: =F36+G36 -> 43 | H37: =H36+I36 -> 39 | J37: =J36+K36 -> 62 | L37: =L36+M36 -> 41 | N37: =N36+O36 -> 185 | P37: =P36+Q36 -> 905
A42: Summary | D42: Cumm MARCH-26 | F42: 1st April | H42: 2nd April | J42: 3rd April | L42: 4th April | N42: Cummulative April'26 | P42: Cummulative NGC
A43: Entity Name | D43: New Connection Done & Gasified | E43: Old Connection Done & Gasified | F43: New Connection Done & Gasified | G43: Old Connection Done & Gasified | H43: New Connection Done & Gasified | I43: Old Connection Done & Gasified | J43: New Connection Done & Gasified | K43: Old Connection Done & Gasified | L43: New Connection Done & Gasified | M43: Old Connection Done & Gasified | N43: New Connection Done & Gasified | O43: Old Connection Done & Gasified | P43: New Connection Done & Gasified | Q43: Old Connection Done & Gasified | R43: Grand total NGC
A46: HPCL | D46: =D17 -> 2366 | E46: =E17 -> 2022 | F46: =F17 -> 154 | G46: =G17 -> 227 | H46: =H17 -> 229 | I46: =I17 -> 123 | J46: =J17 -> 229 | K46: =K17 -> 115 | ... M46: =M17 -> 104 | N46: =F46+H46+J46+L46 -> 801 | O46: =G46+I46+K46+M46 -> 569 | P46: =D46+N46 -> 3167 | Q46: =E46+O46 -> 2591 | R46: =P46+Q46 -> 5758
A47: HOGPL | D47: =D26 -> 84 | E47: =E26 -> 475 | F47: =F26 -> 12 | G47: =G26 -> 18 | H47: =H26 -> 1 | I47: =I26 -> 36 | J47: =J26 -> 0 | K47: =K26 -> 27 | ... M47: =M26 -> 74 | N47: =F47+H47+J47+L47 -> 15 | O47: =G47+I47+K47+M47 -> 155 | P47: =D47+N47 -> 99 | Q47: =E47+O47 -> 630 | R47: =P47+Q47 -> 729
A48: BGL | D48: =D36 -> 212 | E48: =E36 -> 508 | F48: =F36 -> 0 | G48: =G36 -> 43 | H48: =H36 -> 1 | I48: =I36 -> 38 | J48: =J36 -> 2 | K48: =K36 -> 60 | ... M48: =M36 -> 39 | N48: =F48+H48+J48+L48 -> 5 | O48: =G48+I48+K48+M48 -> 180 | P48: =D48+N48 -> 217 | Q48: =E48+O48 -> 688 | R48: =P48+Q48 -> 905
A49: Total | D49: =SUM(D46:D48) -> 2662 | E49: =SUM(E46:E48) -> 3005 | F49: =SUM(F46:F48) -> 166 | G49: =SUM(G46:G48) -> 288 | H49: =SUM(H46:H48) -> 231 | I49: =SUM(I46:I48) -> 197 | J49: =SUM(J46:J48) -> 231 | K49: =SUM(K46:K48) -> 202 | ... R49: =SUM(R46:R48) -> 7392
A50: Grand Total | D50: =D49+E49 -> 5667 | F50: =F49+G49 -> 454 | H50: =H49+I49 -> 428 | J50: =J49+K49 -> 433 | L50: =L49+M49 -> 410 | N50: =N49+O49 -> 1725 | P50: =P49+Q49 -> 7392

Sheet Sheet1
A1: NGC Progress MIS – Gasified Geographical Area (HPCL & JVs)
A2: HPCL
A3: GA ID | B3: GA Area | C3: State/UTs | D3: April-Feb' 26 Average | E3: Traget(PNGRB) 1st Apr-30th June | F3: Daily New Connection April | G3: Cum. Connection
A6: 10.37 | B6: Bareilly, Rampur, Pilibhit | C6: UP | D6: 68 | E6: 200 | F6: 0 | G6: 107
A7: 10.47 | B7: Darjeeling, Jalpaiguri & Uttar Dinajpur | C7: WB | D7: 17 | E7: 100 | F7: 0 | G7: 307
A8: 10.39 | B8: Etah, Farrukhabad, Hardoi | C8: UP | D8: 25 | E8: 200 | F8: 0 | G8: 122
A9: 10.48 | B9: Howrah & Hooghly | C9: WB | D9: 11 | E9: 120 | F9: 0 | G9: 80
A10: 10.49 | B10: Nadia & North 24 Parganas | C10: WB | D10: 28 | E10: 120 | F10: 0
A11: 10.45 | B11: Shahjahanpur Badaun | C11: UP | D11: 70 | E11: 200 | F11: 0 | G11: 194
A12: 9.19 | B12: Sonipat - Jind GA | C12: Haryana | D12: 87 | E12: 150 | F12: 0 | G12: 71
A13: 10.43 | B13: Mainpuri Kannauj | C13: UP | D13: 42 | E13: 200 | F13: 0 | G13: 92
A14: 10.46 | B14: Nainital Bijnor | C14: UK/UP | D14: 73 | E14: 150 | F14: 0 | G14: 110
A15: 10.5 | B15: South 24 Parganas | C15: WB | D15: 5 | E15: 24 | F15: 0 | G15: 21
A16: 11.44 | B16: Dausa, Karauli, Sawai Madhopur & Tonk | C16: RJ | D16: 3 | E16: 50 | F16: 0 | G16: 104
A17: Total | D17: =SUM(D6:D16) -> 429 | E17: 1514 | F17: =SUM(F6:F16) -> 0 | G17: =SUM(G6:G16) -> 1208
A18: Grand Total | D18: =D17+E17 -> 1943 | F18: 0
A20: HOGPL | D20: Cum MARCH-26 | F20: 1st April
A21: GA ID | B21: GA Area | C21: State/UTs | D21: New Connection Done & Gasified | E21: Old Connection Done & Gasified | F21: New Connection Done & Gasified
A24: 8.03 | B24: Ambala & Kurukshetra Districts | C24: Haryana | D24: 74 | E24: 251 | F24: 12
A25: 8.04 | B25: Kolhapur District | C25: Maharashtra | D25: 10 | E25: 224 | F25: 0
A26: Total | D26: =SUM(D24:D25) -> 84 | E26: =SUM(E24:E25) -> 475 | F26: =SUM(F24:F25) -> 12
A27: Grand Total | D27: =D26+E26 -> 559 | F27: =F26+#REF! -> #REF!
A29: BGL | D29: Cum MARCH-26 | F29: 1st April
A30: GA ID | B30: GA Area | C30: State/UTs | D30: New Connection Done & Gasified | E30: Old Connection Done & Gasified | F30: New Connection Done & Gasified
A33: 99.09 | B33: Hyderabad | C33: Telangana | D33: 192 | E33: 261 | F33: 0
A34: 1.04 | B34: Kakinada | C34: Andhra Pradesh | D34: 5 | E34: 107 | F34: 0
A35: 99.06 | B35: Vijaywada | C35: Andhra Pradesh | D35: 15 | E35: 140 | F35: 0
A36: Total | D36: =SUM(D33:D35) -> 212 | E36: =SUM(E33:E35) -> 508 | F36: =SUM(F33:F35) -> 0
A37: Grand Total | D37: =D36+E36 -> 720 | F37: =F36+#REF! -> #REF!

Sheet Sheet2
K1: NGC | L1: LMC | M1: Reg | N1: CNMD
A2: Gasified Amera | B2: LMC | C2: vendor | D2: team | F2: lmc | G2: only ngc 2 nos | K2: 4388 | L2: 5506 | M2: 3779
E3: 2 | F3: 4

Sheet calculation 30 mar
A1: DPNG
A3: GA Name | B3: Cumm. NGC as on 31.12.2025
C4: Jan-Mar | D4: LMC-NGC-Focused | E4: Total
A5: Jind & Sonipat | B5: 4032 | C5: 266 | D5: 52 | E5: =B5+C5+D5 -> 4350
A6: Bareilly, Pilibhit & Rampur | B6: 724 | C6: 496 | D6: 67 | E6: =B6+C6+D6 -> 1287
A7: Farukhabad, Etah, and Hardoi | B7: 840 | C7: 178 | D7: 177 | E7: =B7+C7+D7 -> 1195
A8: Mainpuri & Kannauj | B8: 681 | C8: 516 | D8: 0 | E8: =B8+C8+D8 -> 1197
A9: Nainital & Bijnor | B9: 1430 | C9: 485 | D9: 0 | E9: =B9+C9+D9 -> 1915
A10: Shahjahanpur & Badaun | B10: 2603 | C10: 443 | D10: 306 | E10: =B10+C10+D10 -> 3352
A11: Howrah & Hooghly | B11: 109 | C11: 128 | D11: 397 | E11: =B11+C11+D11 -> 634
A12: Nadia & North 24 Parganas | B12: 256 | C12: 170 | D12: 584 | E12: =B12+C12+D12 -> 1010
A13: South 24 Parganas | B13: 53 | C13: 41 | D13: 0 | E13: =B13+C13+D13 -> 94
A14: Darjilling,Jalpaiguri,Uttar dinajpur | B14: 67 | C14: 627 | D14: 766 | E14: =B14+C14+D14 -> 1460
A15: Dumka,Banka,Godda,Jamtara,Pakur& Sahibganj | B15: 0 | C15: 0 | D15: 0 | E15: =B15+C15+D15 -> 0
A16: Maldah, Birbhum, Murshidabad, Dakshin Dinajpur | B16: 0 | C16: 0 | D16: 0 | E16: =B16+C16+D16 -> 0
A17: Tonk,Sawai Madhopur.Dausa,karauli | B17: 34 | C17: 56 | D17: 0 | E17: =B17+C17+D17 -> 90
A18: Total | B18: =SUM(B5:B17) -> 10829 | C18: =SUM(C5:C17) -> 3406 | D18: =SUM(D5:D17) -> 2349 | E18: =SUM(E5:E17) -> 16584

Sheet Revised target
A1: S.no | B1: GA ID | C1: Geographical Area/ CGD Networks | D1: State/ Union Territory | E1: Authorized CGD Entity New Name | F1: Date of Authorization | G1: Target completion period (Years) | H1: Date of Target Completion | I1: DPNG Target (Drive) | J1: Connected to Billed | K1: DPNG Registration Target | L1: Commercial Connection Target (Drive) | M1: Reason for change in target
A2: 1 | B2: 9.19 | C2: Sonipat District (EAAA) & Jind District | D2: Haryana | E2: Hindustan Petroleum Corporation Limited | F2: 43369 | G2: 8 | H2: 47026 | I2: 10000 | J2: 10000 | K2: 10000 | L2: 20 | M2: As Sonipat city is authorized to GAIL Gas, we are left with Jind district and the peripheral areas of Sonipat, which have relatively low potential
A3: 2 | B3: 10.37 | C3: Bareilly (EAAA) District, Pilibhit and Rampur Districts | D3: Uttar Pradesh | E3: Hindustan Petroleum Corporation Limited | F3: 43553 | G3: 8 | H3: 47208 | I3: 10000 | J3: 10000 | K3: 20000 | L3: 5 | M3: The major potential area of GA 10.37 is Bareilly city, which has been assigned to CUGL.
A4: 3 | B4: 10.39 | C4: Farrukhabad, Etah and Hardoi Districts | D4: Uttar Pradesh | E4: Hindustan Petroleum Corporation Limited | F4: 43553 | G4: 8 | H4: 47208 | I4: 15000 | J4: 25000 | K4: 30000 | L4: 20
A5: 4 | B5: 10.43 | C5: Mainpuri and Kannauj Districts | D5: Uttar Pradesh | E5: Hindustan Petroleum Corporation Limited | F5: 43553 | G5: 8 | H5: 47208 | I5: 10000 | J5: 5000 | K5: 20000 | L5: 20
A6: 5 | B6: 10.45 | C6: Shahjahanpur and Budaun Districts | D6: Uttar Pradesh | E6: Hindustan Petroleum Corporation Limited | F6: 43553 | G6: 8 | H6: 47208 | I6: 15000 | J6: 20000 | K6: 30000 | L6: 5
A7: 6 | B7: 10.47 | C7: Darjeeling, Jalpaiguri and Uttar Dinajpur Districts | D7: West Bengal | E7: Hindustan Petroleum Corporation Limited | F7: 29-03-2019 (New start date 01.01.2021) | G7: 10 | H7: 48304 | I7: 10000 | J7: 15000 | K7: 30000 | L7: 10 | M7: Siliguri is the major business hub and approvals for laying the MDP network are still pending due to the elections, and are expected by 15th May.
A8: 7 | B8: 10.48 | C8: Howrah (EAAA) District and Hoogly (EAAA) District | D8: West Bengal | E8: Hindustan Petroleum Corporation Limited | F8: 29-03-2019 (New start date 01.01.2023) | G8: 8 | H8: 47848 | I8: 10000 | J8: 10000 | K8: 40000 | L8: 10 | M8: The major potential areas of Kolkata town are with Bengal Gas, while the peripheral semi-urban and rural areas with relatively lower potential are with HPCL. Additionally, due to the elections in West Bengal, approval for laying the MDP network has been delayed and is expected by 15th May.
A9: 8 | B9: 10.49 | C9: Nadia (EAAA) District and North 24 Parganas (EAAA) District | D9: West Bengal | E9: Hindustan Petroleum Corporation Limited | F9: 29-03-2019 (New start date 01.01.2023) | G9: 8 | H9: 47848 | I9: 10000 | J9: 10000 | K9: 30000 | L9: 20 | M9: The major potential areas of Kolkata town are with Bengal Gas, while the peripheral semi-urban and rural areas with relatively lower potential are with HPCL. Additionally, due to the elections in West Bengal, approval for laying the MDP network has been delayed and is expected by 15th May.
A10: 9 | B10: 10.5 | C10: South 24 Parganas (EAAA) District | D10: West Bengal | E10: Hindustan Petroleum Corporation Limited | F10: 29-03-2019 (New start date 01.01.2022) | G10: 8 | H10: 47573 | I10: 5000 | J10: 5000 | K10: 10000 | L10: 10 | M10: GA is not yet gasified. The major potential areas of Kolkata town are with Bengal Gas, while the peripheral semi-urban and rural areas with relatively lower potential are with HPCL. Additionally, due to the elections in West Bengal, approval for laying the MDP network has been delayed and is expected by 15th May.
A11: 10 | B11: 11.44 | C11: Dausa, Karauli, Sawai Madhopur and Tonk districts | D11: Rajasthan | E11: Hindustan Petroleum Corporation Limited | F11: 44635 | G11: 8 | H11: 47573 | I11: 15000 | J11: 7500 | K11: 30000 | L11: 5
A12: 11 | B12: 11A.03 | C12: Birbhum, Murshidabad, Maldah & Dakshin Dinajpur districts | D12: West Bengal | E12: Hindustan Petroleum Corporation Limited | F12: 44729 | G12: 8 | H12: 47664 | I12: 5000 | J12: 5000 | K12: 30000 | L12: 5 | M12: The GA is yet to be gasified, apart from the WB state election where all approvals of MDP laying has come to halt
A13: 12 | B13: 11A.02 | C13: Banka, Dumka, Godda. Jamtara, Pakur & Sahibganj | F13: 14th- June-22 | G13: 8 | I13: 5000 | J13: 5000 | K13: 10000 | L13: 5 | M13: The GA is yet to be gasified, and due to the West Bengal state elections, all approvals for MDP laying have come to a halt.
A14: 13 | B14: 10.46 | C14: Nainital Bijnor | D14: West Bengal | E14: Hindustan Petroleum Corporation Limited | F14: 29th- Mar-19 | G14: 8 | I14: 10000 | J14: 10000 | K14: 20000 | L14: 5 | M14: The GA is yet to be gasified
A15: Total | I15: =SUM(I2:I14) -> 130000 | J15: =SUM(J2:J14) -> 137500 | K15: =SUM(K2:K14) -> 310000 | L15: =SUM(L2:L14) -> 140

Sheet Govt
A1: GA Name | B1: Govt / Institution/PSU/High Rise Name | C1: Household No. | D1: Commercial No. | E1: Consumption (SCM) | F1: Comments
A2: MALDAH GA | B2: BSF(MALDAH) | C2: 500 | D2: 4 | E2: 5100 | F2: MDPE work initiated
A3: MALDAH GA | B3: Railway | C3: 1500 | D3: 0 | E3: =1500*0.2*30 -> 9000 | F3: Agreement executed
A4: NN24 | B4: ISSER | C4: 70 | D4: 1 | E4: 6500 | F4: Area gasified
A5: NN24 | B5: AIIMS | C5: 171 | D5: 6 | E5: 13000 | F5: Agreement executed
A6: NN24 | B6: BSF (Kalyani) | C6: 325 | D6: 5 | E6: 8000 | F6: Proposal submitted to cantonment authorities
A7: NN24 | B7: *Sapoorji Palonji* | C7: 15000 | D7: 0 | E7: =(3000*0.2*30) -> 18000 | F7: High-rise development comprising 15,000 households; approval secured for 3,000 households
A8: S24 | B8: IIM (Kolkata) | C8: 75 | D8: 8 | E8: 10000 | F8: Proposal submitted to the college
A9: SB | B9: Rosa Township Reliance(Power plant),Shahjahanpur | C9: 350 | D9: 2 | E9: 8000 | F9: Area gasified
A10: SB | B10: Kribhco Nagar Township,Shahjahanpur | C10: 500 | D10: 1 | E10: 5000 | F10: Agreement executed
A11: SB | B11: Army Cantonment Shahjahanpur | C11: 600 | D11: 4 | E11: 6000 | F11: Approval under process
A12: BRP | B12: CRPF(RAMPUR) | C12: 900 | D12: 5 | E12: 7000 | F12: Concerned authority contacted and approval request letter submitted
A13: BRP | B13: POLITECHNIC COLLEGE- STUDENT MESS | C13: 0 | D13: 2 | E13: =10*30 -> 300 | F13: Approval from the college is pending
A14: BRP | B14: IFFCO | C14: 400 | D14: 2 | E14: 8000 | F14: MDPE work in progress
A15: DARJELLING | B15: BSF(SILLIGURI)& (DANI NAGAR) | C15: 1600 | D15: 4 | E15: =1600*0.2*30+90 -> 9690 | F15: Gasification proposal submitted to cantonment authorities
A16: Mainpuri- Kannauj | B16: Government Colony(Mainpuri) | C16: 600 | D16: 0 | E16: =(600*0.2*30) -> 3600 | F16: Approval received from DM office
A17: Mainpuri- Kannauj | B17: Government Colony(Kannauj) | C17: 200 | D17: 0 | E17: =(200*0.2*30) -> 1200 | F17: Approval received from DM office
A18: Tonk | B18: CSWRI | C18: 300 | D18: 2 | E18: 3600 | F18: Contacted the customer
A19: Tonk | B19: CISF | C19: 250 | D19: 16 | E19: 10000 | F19: Final agreement to be signed.
A20: Tonk | B20: Police line | C20: 300 | D20: 1 | E20: 3500 | F20: The SSP has been contacted for approval.
A21: EFH | B21: Army Cant(Farukhabad) | C21: 1000 | D21: 2 | E21: 8000 | F21: Approval under process

Sheet GSA details
A1: Details of GSA s signed after 01.01.2026
A2: Sr no.- | B2: Name of customer | C2: GA Name | D2: GSA type | E2: Estimated consumption in SCMD | F2: Date of GSA | G2: Status ( Started/Not started )
A3: 1 | B3: Shree Durga Texcoat Pvt Ltd | C3: JS | D3: Industrial | E3: 300 | F3: 19.03.2026 | G3: Not Started
A4: 2 | B4: Anand Knit | C4: JS | D4: Industrial | E4: 500 | F4: 19.03.2026 | G4: Started
A5: 3 | B5: Shatabdi Export | C5: JS | D5: Industrial | E5: 1500 | F5: 18.03.2026 | G5: Started
A6: 4 | B6: Bansal Processing house | C6: JS | D6: Industrial | E6: 1300 | F6: 19.03.2026 | G6: Started
A7: 5 | B7: BCL Fabrics | C7: JS | D7: Industrial | E7: 500 | F7: 18.03.2026 | G7: Started
A8: 6 | B8: Shree Karangar Textile Pvt Ltd | C8: JS | D8: Industrial | E8: 200 | F8: 19.03.2026 | G8: Started
A9: 7 | B9: Neelam Lace | C9: JS | D9: Industrial | E9: 150 | F9: 08.01.2026 | G9: Started
A10: 8 | B10: Ajit Industries 3 | C10: JS | D10: Industrial | E10: 100 | F10: 06.02.2026 | G10: Started
A11: 9 | B11: Krishna Polymers | C11: JS | D11: Industrial | E11: 600 | F11: 11.01.2026 | G11: Started
A12: 10 | B12: Poddar Tyres and Rubber | C12: JS | D12: Industrial | E12: 200 | F12: 02.01.2026 | G12: Not Started
A13: 11 | B13: Vihan Textiles | C13: JS | D13: Industrial | E13: 1300 | F13: 22.03.2026 | G13: Started
A14: 12 | B14: Shree Karshni Brass Extrusion | C14: JS | D14: Industrial | E14: 300 | F14: 20.03.2026 | G14: Not Started
... A54: 52 | B54: Zila Dugdh Utpadak Sahkari Sangh Limited | C54: DKSMT | D54: Industrial | E54: 450 | F54: 23.02.2026 | G54: Not Started
D55: Total | E55: =SUM(E3:E54) -> 71362

Sheet INDUSCOMMERCIAL
A1: Ind/Comm Commissioning
A2: JS | B2: HH | C2: NN24 | D2: DARJELLING | E2: MK | F2: BRP
A3: 1.Neelam lace | B3: Shakambari Ispat | C3: IISER:1 | D3: PRITI MISTHAN(MARCH) | E3: SUDITI GLOBAL ACADEMY | F3: MOOD FOOD
A4: 2.Ajit industries | B4: Nursing Home. | D4: DAS MiSTHAN BHANDAR
A5: 3.Krishna polymers | D5: PAKURTALA MISTHAN BHANDAR
A6: 4.Poddar tyres
A7: 5.Bcl fabrics
A8: 6.Bansal processing house
A9: 7.Shatabdi exports
A10: 8.Anand knit
A11: 9.Vihan textiles
A12: 10. Karangar textiles pvt ltd.
A13: SHRI DURGA TEXCOAT
A14: SHRI KARSHNI BRASS EXTRUSION
A15: HSIIDC Foodpark

Sheet target customers
A1: SL No | B1: Business / Customer Name | C1: GA Name | D1: District / Location | E1: Expected Commissioning | F1: Expected Volume (SCMD)
A2: 1 | B2: Hotel Tara Chicken Corner | C2: BRP | D2: Rampur | E2: 46174 | F2: 9.88
A3: 2 | B3: Karim Chicken Corner | C3: BRP | D3: Rampur | E3: 46143 | F3: 20.58
A4: 3 | B4: Noor-E-Shama | C4: BRP | D4: Rampur | E4: 46204 | F4: 21.41
A5: 4 | B5: Shivam Fast Food | C5: BRP | D5: Rampur | E5: 46143 | F5: 12.35
A6: 5 | B6: Kesar Food | C6: BRP | D6: Rampur | E6: 46174 | F6: 24.7
A7: 6 | B7: Manthan Restaurant | C7: BRP | D7: Rampur | E7: 46174 | F7: 23
A8: 7 | B8: Food Plaza | C8: BRP | D8: Rampur | E8: 46204 | F8: 9.88
A9: 8 | B9: Dosa Darbar | C9: BRP | D9: Rampur | E9: 46204 | F9: 16.47
A10: 9 | B10: Biggies Pizza | C10: BRP | D10: Rampur | E10: 46235 | F10: 37.05
A11: 10 | B11: Hungry Point | C11: BRP | D11: Rampur | E11: 46235 | F11: 16.47
A12: 11 | B12: Opal restaurant | C12: BRP | D12: Rampur | E12: April'26 | F12: 50
A13: 12 | B13: Radiance hotel | C13: BRP | D13: Rampur | E13: May'26 | F13: 40
A14: 13 | B14: Punjabi Tadka | C14: BRP | D14: Rampur | E14: 46204 | F14: 24.7
A15: 14 | B15: Delhi-6-Zaika | C15: BRP | D15: Rampur | E15: 46235 | F15: 24.7
A16: 15 | B16: Hotel Delite | C16: BRP | D16: Rampur | E16: 46266 | F16: 14.82
A17: 16 | B17: Bombay Hotel | C17: BRP | D17: Rampur | E17: 46266 | F17: 42.81
A18: 17 | B18: Hotel Krishna | C18: BRP | D18: Rampur | E18: 46266 | F18: 13.17
A19: 18 | B19: Karims Food | C19: BRP | D19: Rampur | E19: 46266 | F19: 39.52
A20: 19 | B20: Batra Restaurant | C20: BRP | D20: Rampur | E20: 46296 | F20: 21.41
A21: 20 | B21: Zaika Darbar | C21: BRP | D21: Rampur | E21: 46296 | F21: 34.58
A22: 21 | B22: Dominos | C22: BRP | D22: Rampur | E22: 46296 | F22: 27.99
A23: 22 | B23: Chicken King | C23: BRP | D23: Rampur | E23: 46357 | F23: 45.5
A24: 23 | B24: The Olive & Cheese | C24: BRP | D24: Rampur | E24: 46357 | F24: 36.4
A25: 24 | B25: Al-Baike Restaurant | C25: BRP | D25: Rampur | E25: 46357 | F25: 36.4
... A44: 43 | B44: Utsav Green Hotel & Restaurant | C44: BRP | D44: Pilibhit | E44: 46388 | F44: 13
A45: 44 | B45: Pawan Sweets | C45: BRP | D45: Pilibhit | E45: May'26 | F45: 50
A46: 45 | B46: Hotel Solitaire | C46: BRP | D46: Pilibhit | E46: May'26 | F46: 50
A47: 46 | B47: Sino India | C47: JS | D47: Sonipat | E47: 46143 | F47: 4000
A48: 47 | B48: Shellz India | C48: JS | D48: Sonipat | E48: 46143 | F48: 1200
A49: 48 | B49: Fine Foods India | C49: JS | D49: Sonipat | E49: June'26 | F49: 100
A50: 49 | B50: Polyplast India | C50: JS | D50: Sonipat | E50: June'26 | F50: 200
A51: 50 | B51: HSIIDC Mega Food Park | C51: JS | D51: Sonipat | E51: Mar'26 | F51: 150
A52: 51 | B52: Chicken Processing Plant | C52: NN24 | D52: Nadia | E52: 46266 | F52: 9000
A53: 52 | B53: Chicken Rendering Plant | C53: NN24 | D53: Nadia | E53: 46266 | F53: 600
A54: 53 | B54: IISER | C54: NN24 | D54: Nadia | E54: 46082 | F54: 175
A55: 54 | B55: BSF | C55: NN24 | D55: Nadia | E55: 46174 | F55: 200
A56: 55 | B56: AIIMS | C56: NN24 | D56: Nadia | E56: 46143 | F56: 430
A57: 56 | B57: 10 Commercial Customers (Paharpur) | C57: Darjeeling GA | D57: Jalpaiguri | E57: 46082 | F57: 400
A58: 57 | B58: Pakurtala Mistanna Bhandar, Kartik Sweets, Lords Confectionery, Biryani House, Priti Mistanna Bhandar, Hazi Biryani, BB Biryani, Roy Hotel, Pritam Hotel, Montu Miro | C58: Darjeeling GA | D58: Jalpaiguri | E58: 46082 | F58: 200
...
